{
 "cells": [
  {
   "cell_type": "code",
   "execution_count": 1,
   "metadata": {},
   "outputs": [
    {
     "ename": "ModuleNotFoundError",
     "evalue": "No module named 'tensorflow'",
     "output_type": "error",
     "traceback": [
      "\u001b[1;31m---------------------------------------------------------------------------\u001b[0m",
      "\u001b[1;31mModuleNotFoundError\u001b[0m                       Traceback (most recent call last)",
      "\u001b[1;32m~\\AppData\\Local\\Temp/ipykernel_372/2597781833.py\u001b[0m in \u001b[0;36m<module>\u001b[1;34m\u001b[0m\n\u001b[0;32m      3\u001b[0m \u001b[1;31m# (x_train, y_train), (x_test, y_test) = keras.datasets.mnist.load_data()\u001b[0m\u001b[1;33m\u001b[0m\u001b[1;33m\u001b[0m\u001b[0m\n\u001b[0;32m      4\u001b[0m \u001b[1;32mimport\u001b[0m \u001b[0msklearn\u001b[0m\u001b[1;33m.\u001b[0m\u001b[0mdatasets\u001b[0m \u001b[1;32mas\u001b[0m \u001b[0mds\u001b[0m\u001b[1;33m\u001b[0m\u001b[1;33m\u001b[0m\u001b[0m\n\u001b[1;32m----> 5\u001b[1;33m \u001b[1;32mimport\u001b[0m \u001b[0mkeras\u001b[0m\u001b[1;33m\u001b[0m\u001b[1;33m\u001b[0m\u001b[0m\n\u001b[0m\u001b[0;32m      6\u001b[0m \u001b[0mkeras\u001b[0m\u001b[1;33m.\u001b[0m\u001b[0mdatasets\u001b[0m\u001b[1;33m\u001b[0m\u001b[1;33m\u001b[0m\u001b[0m\n\u001b[0;32m      7\u001b[0m \u001b[1;31m# x_train.shape\u001b[0m\u001b[1;33m\u001b[0m\u001b[1;33m\u001b[0m\u001b[0m\n",
      "\u001b[1;32md:\\anaconda3\\lib\\site-packages\\keras\\__init__.py\u001b[0m in \u001b[0;36m<module>\u001b[1;34m\u001b[0m\n\u001b[0;32m     19\u001b[0m \"\"\"\n\u001b[0;32m     20\u001b[0m \u001b[1;31m# pylint: disable=unused-import\u001b[0m\u001b[1;33m\u001b[0m\u001b[1;33m\u001b[0m\u001b[0m\n\u001b[1;32m---> 21\u001b[1;33m \u001b[1;32mfrom\u001b[0m \u001b[0mtensorflow\u001b[0m\u001b[1;33m.\u001b[0m\u001b[0mpython\u001b[0m \u001b[1;32mimport\u001b[0m \u001b[0mtf2\u001b[0m\u001b[1;33m\u001b[0m\u001b[1;33m\u001b[0m\u001b[0m\n\u001b[0m\u001b[0;32m     22\u001b[0m \u001b[1;32mfrom\u001b[0m \u001b[0mkeras\u001b[0m \u001b[1;32mimport\u001b[0m \u001b[0mdistribute\u001b[0m\u001b[1;33m\u001b[0m\u001b[1;33m\u001b[0m\u001b[0m\n\u001b[0;32m     23\u001b[0m \u001b[1;33m\u001b[0m\u001b[0m\n",
      "\u001b[1;31mModuleNotFoundError\u001b[0m: No module named 'tensorflow'"
     ]
    }
   ],
   "source": [
    "# from tensorflow import keras \n",
    "# import matplotlib.pyplot as plt\n",
    "# (x_train, y_train), (x_test, y_test) = keras.datasets.mnist.load_data()\n",
    "import sklearn.datasets as ds\n",
    "import keras\n",
    "keras.datasets\n",
    "# x_train.shape"
   ]
  },
  {
   "cell_type": "code",
   "execution_count": 4,
   "metadata": {},
   "outputs": [
    {
     "ename": "ModuleNotFoundError",
     "evalue": "No module named 'matplotlib'",
     "output_type": "error",
     "traceback": [
      "\u001b[1;31m---------------------------------------------------------------------------\u001b[0m",
      "\u001b[1;31mModuleNotFoundError\u001b[0m                       Traceback (most recent call last)",
      "\u001b[1;32mc:\\Users\\Ali\\chap-2.ipynb Cell 2'\u001b[0m in \u001b[0;36m<cell line: 1>\u001b[1;34m()\u001b[0m\n\u001b[1;32m----> <a href='vscode-notebook-cell:/c%3A/Users/Ali/chap-2.ipynb#ch0000001?line=0'>1</a>\u001b[0m \u001b[39mimport\u001b[39;00m \u001b[39mmatplotlib\u001b[39;00m \u001b[39mas\u001b[39;00m \u001b[39mmpl\u001b[39;00m\n\u001b[0;32m      <a href='vscode-notebook-cell:/c%3A/Users/Ali/chap-2.ipynb#ch0000001?line=1'>2</a>\u001b[0m \u001b[39mimport\u001b[39;00m \u001b[39mmatplotlib\u001b[39;00m\u001b[39m.\u001b[39;00m\u001b[39mpyplot\u001b[39;00m \u001b[39mas\u001b[39;00m \u001b[39mplt\u001b[39;00m\n\u001b[0;32m      <a href='vscode-notebook-cell:/c%3A/Users/Ali/chap-2.ipynb#ch0000001?line=3'>4</a>\u001b[0m some_digit \u001b[39m=\u001b[39m x_train[\u001b[39m0\u001b[39m]\n",
      "\u001b[1;31mModuleNotFoundError\u001b[0m: No module named 'matplotlib'"
     ]
    }
   ],
   "source": [
    "import matplotlib as mpl\n",
    "import matplotlib.pyplot as plt\n",
    "\n",
    "some_digit = x_train[0]\n",
    "some_digit_image = some_digit.reshape(28, 28)\n",
    "plt.imshow(some_digit_image, cmap=\"binary\")\n",
    "plt.axis(\"off\")\n",
    "plt.show()"
   ]
  },
  {
   "cell_type": "code",
   "execution_count": 36,
   "metadata": {},
   "outputs": [],
   "source": [
    "y_train_5 = (y_train == 5) # True for all 5s, False for all other digits\n",
    "y_test_5 = (y_test == 5)"
   ]
  },
  {
   "cell_type": "code",
   "execution_count": 42,
   "metadata": {},
   "outputs": [
    {
     "name": "stderr",
     "output_type": "stream",
     "text": [
      "ERROR:root:Internal Python error in the inspect module.\n",
      "Below is the traceback from this internal error.\n",
      "\n"
     ]
    },
    {
     "name": "stdout",
     "output_type": "stream",
     "text": [
      "Traceback (most recent call last):\n",
      "  File \"D:\\Anaconda\\lib\\site-packages\\IPython\\core\\interactiveshell.py\", line 3326, in run_code\n",
      "    exec(code_obj, self.user_global_ns, self.user_ns)\n",
      "  File \"<ipython-input-42-02b0a1150385>\", line 4, in <module>\n",
      "    sgd_clf.fit(x_train, y_train_5)\n",
      "  File \"D:\\Anaconda\\lib\\site-packages\\sklearn\\linear_model\\stochastic_gradient.py\", line 713, in fit\n",
      "    sample_weight=sample_weight)\n",
      "  File \"D:\\Anaconda\\lib\\site-packages\\sklearn\\linear_model\\stochastic_gradient.py\", line 529, in _fit\n",
      "    accept_large_sparse=False)\n",
      "  File \"D:\\Anaconda\\lib\\site-packages\\sklearn\\utils\\validation.py\", line 719, in check_X_y\n",
      "    estimator=estimator)\n",
      "  File \"D:\\Anaconda\\lib\\site-packages\\sklearn\\utils\\validation.py\", line 539, in check_array\n",
      "    % (array.ndim, estimator_name))\n",
      "ValueError: Found array with dim 3. Estimator expected <= 2.\n",
      "\n",
      "During handling of the above exception, another exception occurred:\n",
      "\n",
      "Traceback (most recent call last):\n",
      "  File \"D:\\Anaconda\\lib\\site-packages\\IPython\\core\\interactiveshell.py\", line 2040, in showtraceback\n",
      "    stb = value._render_traceback_()\n",
      "AttributeError: 'ValueError' object has no attribute '_render_traceback_'\n",
      "\n",
      "During handling of the above exception, another exception occurred:\n",
      "\n",
      "Traceback (most recent call last):\n",
      "  File \"D:\\Anaconda\\lib\\site-packages\\IPython\\core\\ultratb.py\", line 1101, in get_records\n",
      "    return _fixed_getinnerframes(etb, number_of_lines_of_context, tb_offset)\n",
      "  File \"D:\\Anaconda\\lib\\site-packages\\IPython\\core\\ultratb.py\", line 319, in wrapped\n",
      "    return f(*args, **kwargs)\n",
      "  File \"D:\\Anaconda\\lib\\site-packages\\IPython\\core\\ultratb.py\", line 353, in _fixed_getinnerframes\n",
      "    records = fix_frame_records_filenames(inspect.getinnerframes(etb, context))\n",
      "  File \"D:\\Anaconda\\lib\\inspect.py\", line 1502, in getinnerframes\n",
      "    frameinfo = (tb.tb_frame,) + getframeinfo(tb, context)\n",
      "  File \"D:\\Anaconda\\lib\\inspect.py\", line 1460, in getframeinfo\n",
      "    filename = getsourcefile(frame) or getfile(frame)\n",
      "  File \"D:\\Anaconda\\lib\\inspect.py\", line 696, in getsourcefile\n",
      "    if getattr(getmodule(object, filename), '__loader__', None) is not None:\n",
      "  File \"D:\\Anaconda\\lib\\inspect.py\", line 733, in getmodule\n",
      "    if ismodule(module) and hasattr(module, '__file__'):\n",
      "  File \"D:\\Anaconda\\lib\\site-packages\\tensorflow\\__init__.py\", line 50, in __getattr__\n",
      "    module = self._load()\n",
      "  File \"D:\\Anaconda\\lib\\site-packages\\tensorflow\\__init__.py\", line 44, in _load\n",
      "    module = _importlib.import_module(self.__name__)\n",
      "  File \"D:\\Anaconda\\lib\\importlib\\__init__.py\", line 127, in import_module\n",
      "    return _bootstrap._gcd_import(name[level:], package, level)\n",
      "  File \"<frozen importlib._bootstrap>\", line 1006, in _gcd_import\n",
      "  File \"<frozen importlib._bootstrap>\", line 983, in _find_and_load\n",
      "  File \"<frozen importlib._bootstrap>\", line 965, in _find_and_load_unlocked\n",
      "ModuleNotFoundError: No module named 'tensorflow_core.estimator'\n"
     ]
    },
    {
     "ename": "ValueError",
     "evalue": "Found array with dim 3. Estimator expected <= 2.",
     "output_type": "error",
     "traceback": [
      "\u001b[1;31m---------------------------------------------------------------------------\u001b[0m"
     ]
    }
   ],
   "source": [
    "from sklearn.linear_model import SGDClassifier\n",
    "\n",
    "sgd_clf = SGDClassifier(random_state=42)\n",
    "sgd_clf.fit(x_train, y_train_5)"
   ]
  }
 ],
 "metadata": {
  "interpreter": {
   "hash": "49cb93f377a7abe7414b7b0f21fb3017538004a126cf690fb524202736b7fb92"
  },
  "kernelspec": {
   "display_name": "Python 3.9.7 ('base')",
   "language": "python",
   "name": "python3"
  },
  "language_info": {
   "codemirror_mode": {
    "name": "ipython",
    "version": 3
   },
   "file_extension": ".py",
   "mimetype": "text/x-python",
   "name": "python",
   "nbconvert_exporter": "python",
   "pygments_lexer": "ipython3",
   "version": "3.9.7"
  },
  "orig_nbformat": 4
 },
 "nbformat": 4,
 "nbformat_minor": 2
}
